2023-06-28:21:14:07,386 INFO     [logger.py:35] Webhook is set
2023-06-28:21:14:07,386 INFO     [dispatcher.py:358] Start polling.
2023-06-28:21:14:10,968 ERROR    [dispatcher.py:390] Cause exception while getting updates.
Traceback (most recent call last):
  File "C:\Users\prp48\Desktop\Projects\Telegram\TelegramBotShop\venv\lib\site-packages\aiogram\dispatcher\dispatcher.py", line 381, in start_polling
    updates = await self.bot.get_updates(
  File "C:\Users\prp48\Desktop\Projects\Telegram\TelegramBotShop\venv\lib\site-packages\aiogram\bot\bot.py", line 110, in get_updates
    result = await self.request(api.Methods.GET_UPDATES, payload)
  File "C:\Users\prp48\Desktop\Projects\Telegram\TelegramBotShop\venv\lib\site-packages\aiogram\bot\base.py", line 236, in request
    return await api.make_request(await self.get_session(), self.server, self.__token, method, data, files,
  File "C:\Users\prp48\Desktop\Projects\Telegram\TelegramBotShop\venv\lib\site-packages\aiogram\bot\api.py", line 140, in make_request
    return check_result(method, response.content_type, response.status, await response.text())
  File "C:\Users\prp48\Desktop\Projects\Telegram\TelegramBotShop\venv\lib\site-packages\aiogram\bot\api.py", line 119, in check_result
    exceptions.ConflictError.detect(description)
  File "C:\Users\prp48\Desktop\Projects\Telegram\TelegramBotShop\venv\lib\site-packages\aiogram\utils\exceptions.py", line 140, in detect
    raise err(cls.text or description)
aiogram.utils.exceptions.TerminatedByOtherGetUpdates: Terminated by other getupdates request; make sure that only one bot instance is running
2023-06-28:21:14:20,978 ERROR    [dispatcher.py:390] Cause exception while getting updates.
Traceback (most recent call last):
  File "C:\Users\prp48\Desktop\Projects\Telegram\TelegramBotShop\venv\lib\site-packages\aiogram\dispatcher\dispatcher.py", line 381, in start_polling
    updates = await self.bot.get_updates(
  File "C:\Users\prp48\Desktop\Projects\Telegram\TelegramBotShop\venv\lib\site-packages\aiogram\bot\bot.py", line 110, in get_updates
    result = await self.request(api.Methods.GET_UPDATES, payload)
  File "C:\Users\prp48\Desktop\Projects\Telegram\TelegramBotShop\venv\lib\site-packages\aiogram\bot\base.py", line 236, in request
    return await api.make_request(await self.get_session(), self.server, self.__token, method, data, files,
  File "C:\Users\prp48\Desktop\Projects\Telegram\TelegramBotShop\venv\lib\site-packages\aiogram\bot\api.py", line 140, in make_request
    return check_result(method, response.content_type, response.status, await response.text())
  File "C:\Users\prp48\Desktop\Projects\Telegram\TelegramBotShop\venv\lib\site-packages\aiogram\bot\api.py", line 119, in check_result
    exceptions.ConflictError.detect(description)
  File "C:\Users\prp48\Desktop\Projects\Telegram\TelegramBotShop\venv\lib\site-packages\aiogram\utils\exceptions.py", line 140, in detect
    raise err(cls.text or description)
aiogram.utils.exceptions.TerminatedByOtherGetUpdates: Terminated by other getupdates request; make sure that only one bot instance is running
2023-06-28:21:14:29,377 ERROR    [dispatcher.py:390] Cause exception while getting updates.
Traceback (most recent call last):
  File "C:\Users\prp48\Desktop\Projects\Telegram\TelegramBotShop\venv\lib\site-packages\aiogram\dispatcher\dispatcher.py", line 381, in start_polling
    updates = await self.bot.get_updates(
  File "C:\Users\prp48\Desktop\Projects\Telegram\TelegramBotShop\venv\lib\site-packages\aiogram\bot\bot.py", line 110, in get_updates
    result = await self.request(api.Methods.GET_UPDATES, payload)
  File "C:\Users\prp48\Desktop\Projects\Telegram\TelegramBotShop\venv\lib\site-packages\aiogram\bot\base.py", line 236, in request
    return await api.make_request(await self.get_session(), self.server, self.__token, method, data, files,
  File "C:\Users\prp48\Desktop\Projects\Telegram\TelegramBotShop\venv\lib\site-packages\aiogram\bot\api.py", line 140, in make_request
    return check_result(method, response.content_type, response.status, await response.text())
  File "C:\Users\prp48\Desktop\Projects\Telegram\TelegramBotShop\venv\lib\site-packages\aiogram\bot\api.py", line 119, in check_result
    exceptions.ConflictError.detect(description)
  File "C:\Users\prp48\Desktop\Projects\Telegram\TelegramBotShop\venv\lib\site-packages\aiogram\utils\exceptions.py", line 140, in detect
    raise err(cls.text or description)
aiogram.utils.exceptions.TerminatedByOtherGetUpdates: Terminated by other getupdates request; make sure that only one bot instance is running
2023-06-28:21:14:39,522 ERROR    [dispatcher.py:390] Cause exception while getting updates.
Traceback (most recent call last):
  File "C:\Users\prp48\Desktop\Projects\Telegram\TelegramBotShop\venv\lib\site-packages\aiogram\dispatcher\dispatcher.py", line 381, in start_polling
    updates = await self.bot.get_updates(
  File "C:\Users\prp48\Desktop\Projects\Telegram\TelegramBotShop\venv\lib\site-packages\aiogram\bot\bot.py", line 110, in get_updates
    result = await self.request(api.Methods.GET_UPDATES, payload)
  File "C:\Users\prp48\Desktop\Projects\Telegram\TelegramBotShop\venv\lib\site-packages\aiogram\bot\base.py", line 236, in request
    return await api.make_request(await self.get_session(), self.server, self.__token, method, data, files,
  File "C:\Users\prp48\Desktop\Projects\Telegram\TelegramBotShop\venv\lib\site-packages\aiogram\bot\api.py", line 140, in make_request
    return check_result(method, response.content_type, response.status, await response.text())
  File "C:\Users\prp48\Desktop\Projects\Telegram\TelegramBotShop\venv\lib\site-packages\aiogram\bot\api.py", line 119, in check_result
    exceptions.ConflictError.detect(description)
  File "C:\Users\prp48\Desktop\Projects\Telegram\TelegramBotShop\venv\lib\site-packages\aiogram\utils\exceptions.py", line 140, in detect
    raise err(cls.text or description)
aiogram.utils.exceptions.TerminatedByOtherGetUpdates: Terminated by other getupdates request; make sure that only one bot instance is running
2023-06-28:21:14:48,528 ERROR    [dispatcher.py:390] Cause exception while getting updates.
Traceback (most recent call last):
  File "C:\Users\prp48\Desktop\Projects\Telegram\TelegramBotShop\venv\lib\site-packages\aiogram\dispatcher\dispatcher.py", line 381, in start_polling
    updates = await self.bot.get_updates(
  File "C:\Users\prp48\Desktop\Projects\Telegram\TelegramBotShop\venv\lib\site-packages\aiogram\bot\bot.py", line 110, in get_updates
    result = await self.request(api.Methods.GET_UPDATES, payload)
  File "C:\Users\prp48\Desktop\Projects\Telegram\TelegramBotShop\venv\lib\site-packages\aiogram\bot\base.py", line 236, in request
    return await api.make_request(await self.get_session(), self.server, self.__token, method, data, files,
  File "C:\Users\prp48\Desktop\Projects\Telegram\TelegramBotShop\venv\lib\site-packages\aiogram\bot\api.py", line 140, in make_request
    return check_result(method, response.content_type, response.status, await response.text())
  File "C:\Users\prp48\Desktop\Projects\Telegram\TelegramBotShop\venv\lib\site-packages\aiogram\bot\api.py", line 119, in check_result
    exceptions.ConflictError.detect(description)
  File "C:\Users\prp48\Desktop\Projects\Telegram\TelegramBotShop\venv\lib\site-packages\aiogram\utils\exceptions.py", line 140, in detect
    raise err(cls.text or description)
aiogram.utils.exceptions.TerminatedByOtherGetUpdates: Terminated by other getupdates request; make sure that only one bot instance is running
2023-06-28:21:14:57,882 ERROR    [dispatcher.py:390] Cause exception while getting updates.
Traceback (most recent call last):
  File "C:\Users\prp48\Desktop\Projects\Telegram\TelegramBotShop\venv\lib\site-packages\aiogram\dispatcher\dispatcher.py", line 381, in start_polling
    updates = await self.bot.get_updates(
  File "C:\Users\prp48\Desktop\Projects\Telegram\TelegramBotShop\venv\lib\site-packages\aiogram\bot\bot.py", line 110, in get_updates
    result = await self.request(api.Methods.GET_UPDATES, payload)
  File "C:\Users\prp48\Desktop\Projects\Telegram\TelegramBotShop\venv\lib\site-packages\aiogram\bot\base.py", line 236, in request
    return await api.make_request(await self.get_session(), self.server, self.__token, method, data, files,
  File "C:\Users\prp48\Desktop\Projects\Telegram\TelegramBotShop\venv\lib\site-packages\aiogram\bot\api.py", line 140, in make_request
    return check_result(method, response.content_type, response.status, await response.text())
  File "C:\Users\prp48\Desktop\Projects\Telegram\TelegramBotShop\venv\lib\site-packages\aiogram\bot\api.py", line 119, in check_result
    exceptions.ConflictError.detect(description)
  File "C:\Users\prp48\Desktop\Projects\Telegram\TelegramBotShop\venv\lib\site-packages\aiogram\utils\exceptions.py", line 140, in detect
    raise err(cls.text or description)
aiogram.utils.exceptions.TerminatedByOtherGetUpdates: Terminated by other getupdates request; make sure that only one bot instance is running
2023-06-28:21:15:07,140 ERROR    [dispatcher.py:390] Cause exception while getting updates.
Traceback (most recent call last):
  File "C:\Users\prp48\Desktop\Projects\Telegram\TelegramBotShop\venv\lib\site-packages\aiogram\dispatcher\dispatcher.py", line 381, in start_polling
    updates = await self.bot.get_updates(
  File "C:\Users\prp48\Desktop\Projects\Telegram\TelegramBotShop\venv\lib\site-packages\aiogram\bot\bot.py", line 110, in get_updates
    result = await self.request(api.Methods.GET_UPDATES, payload)
  File "C:\Users\prp48\Desktop\Projects\Telegram\TelegramBotShop\venv\lib\site-packages\aiogram\bot\base.py", line 236, in request
    return await api.make_request(await self.get_session(), self.server, self.__token, method, data, files,
  File "C:\Users\prp48\Desktop\Projects\Telegram\TelegramBotShop\venv\lib\site-packages\aiogram\bot\api.py", line 140, in make_request
    return check_result(method, response.content_type, response.status, await response.text())
  File "C:\Users\prp48\Desktop\Projects\Telegram\TelegramBotShop\venv\lib\site-packages\aiogram\bot\api.py", line 119, in check_result
    exceptions.ConflictError.detect(description)
  File "C:\Users\prp48\Desktop\Projects\Telegram\TelegramBotShop\venv\lib\site-packages\aiogram\utils\exceptions.py", line 140, in detect
    raise err(cls.text or description)
aiogram.utils.exceptions.TerminatedByOtherGetUpdates: Terminated by other getupdates request; make sure that only one bot instance is running
2023-06-28:21:15:16,461 ERROR    [dispatcher.py:390] Cause exception while getting updates.
Traceback (most recent call last):
  File "C:\Users\prp48\Desktop\Projects\Telegram\TelegramBotShop\venv\lib\site-packages\aiogram\dispatcher\dispatcher.py", line 381, in start_polling
    updates = await self.bot.get_updates(
  File "C:\Users\prp48\Desktop\Projects\Telegram\TelegramBotShop\venv\lib\site-packages\aiogram\bot\bot.py", line 110, in get_updates
    result = await self.request(api.Methods.GET_UPDATES, payload)
  File "C:\Users\prp48\Desktop\Projects\Telegram\TelegramBotShop\venv\lib\site-packages\aiogram\bot\base.py", line 236, in request
    return await api.make_request(await self.get_session(), self.server, self.__token, method, data, files,
  File "C:\Users\prp48\Desktop\Projects\Telegram\TelegramBotShop\venv\lib\site-packages\aiogram\bot\api.py", line 140, in make_request
    return check_result(method, response.content_type, response.status, await response.text())
  File "C:\Users\prp48\Desktop\Projects\Telegram\TelegramBotShop\venv\lib\site-packages\aiogram\bot\api.py", line 119, in check_result
    exceptions.ConflictError.detect(description)
  File "C:\Users\prp48\Desktop\Projects\Telegram\TelegramBotShop\venv\lib\site-packages\aiogram\utils\exceptions.py", line 140, in detect
    raise err(cls.text or description)
aiogram.utils.exceptions.TerminatedByOtherGetUpdates: Terminated by other getupdates request; make sure that only one bot instance is running
2023-06-28:21:15:25,585 ERROR    [dispatcher.py:390] Cause exception while getting updates.
Traceback (most recent call last):
  File "C:\Users\prp48\Desktop\Projects\Telegram\TelegramBotShop\venv\lib\site-packages\aiogram\dispatcher\dispatcher.py", line 381, in start_polling
    updates = await self.bot.get_updates(
  File "C:\Users\prp48\Desktop\Projects\Telegram\TelegramBotShop\venv\lib\site-packages\aiogram\bot\bot.py", line 110, in get_updates
    result = await self.request(api.Methods.GET_UPDATES, payload)
  File "C:\Users\prp48\Desktop\Projects\Telegram\TelegramBotShop\venv\lib\site-packages\aiogram\bot\base.py", line 236, in request
    return await api.make_request(await self.get_session(), self.server, self.__token, method, data, files,
  File "C:\Users\prp48\Desktop\Projects\Telegram\TelegramBotShop\venv\lib\site-packages\aiogram\bot\api.py", line 140, in make_request
    return check_result(method, response.content_type, response.status, await response.text())
  File "C:\Users\prp48\Desktop\Projects\Telegram\TelegramBotShop\venv\lib\site-packages\aiogram\bot\api.py", line 119, in check_result
    exceptions.ConflictError.detect(description)
  File "C:\Users\prp48\Desktop\Projects\Telegram\TelegramBotShop\venv\lib\site-packages\aiogram\utils\exceptions.py", line 140, in detect
    raise err(cls.text or description)
aiogram.utils.exceptions.TerminatedByOtherGetUpdates: Terminated by other getupdates request; make sure that only one bot instance is running
2023-06-28:21:15:35,6 ERROR    [dispatcher.py:390] Cause exception while getting updates.
Traceback (most recent call last):
  File "C:\Users\prp48\Desktop\Projects\Telegram\TelegramBotShop\venv\lib\site-packages\aiogram\dispatcher\dispatcher.py", line 381, in start_polling
    updates = await self.bot.get_updates(
  File "C:\Users\prp48\Desktop\Projects\Telegram\TelegramBotShop\venv\lib\site-packages\aiogram\bot\bot.py", line 110, in get_updates
    result = await self.request(api.Methods.GET_UPDATES, payload)
  File "C:\Users\prp48\Desktop\Projects\Telegram\TelegramBotShop\venv\lib\site-packages\aiogram\bot\base.py", line 236, in request
    return await api.make_request(await self.get_session(), self.server, self.__token, method, data, files,
  File "C:\Users\prp48\Desktop\Projects\Telegram\TelegramBotShop\venv\lib\site-packages\aiogram\bot\api.py", line 140, in make_request
    return check_result(method, response.content_type, response.status, await response.text())
  File "C:\Users\prp48\Desktop\Projects\Telegram\TelegramBotShop\venv\lib\site-packages\aiogram\bot\api.py", line 119, in check_result
    exceptions.ConflictError.detect(description)
  File "C:\Users\prp48\Desktop\Projects\Telegram\TelegramBotShop\venv\lib\site-packages\aiogram\utils\exceptions.py", line 140, in detect
    raise err(cls.text or description)
aiogram.utils.exceptions.TerminatedByOtherGetUpdates: Terminated by other getupdates request; make sure that only one bot instance is running
2023-06-28:21:15:44,186 ERROR    [dispatcher.py:390] Cause exception while getting updates.
Traceback (most recent call last):
  File "C:\Users\prp48\Desktop\Projects\Telegram\TelegramBotShop\venv\lib\site-packages\aiogram\dispatcher\dispatcher.py", line 381, in start_polling
    updates = await self.bot.get_updates(
  File "C:\Users\prp48\Desktop\Projects\Telegram\TelegramBotShop\venv\lib\site-packages\aiogram\bot\bot.py", line 110, in get_updates
    result = await self.request(api.Methods.GET_UPDATES, payload)
  File "C:\Users\prp48\Desktop\Projects\Telegram\TelegramBotShop\venv\lib\site-packages\aiogram\bot\base.py", line 236, in request
    return await api.make_request(await self.get_session(), self.server, self.__token, method, data, files,
  File "C:\Users\prp48\Desktop\Projects\Telegram\TelegramBotShop\venv\lib\site-packages\aiogram\bot\api.py", line 140, in make_request
    return check_result(method, response.content_type, response.status, await response.text())
  File "C:\Users\prp48\Desktop\Projects\Telegram\TelegramBotShop\venv\lib\site-packages\aiogram\bot\api.py", line 119, in check_result
    exceptions.ConflictError.detect(description)
  File "C:\Users\prp48\Desktop\Projects\Telegram\TelegramBotShop\venv\lib\site-packages\aiogram\utils\exceptions.py", line 140, in detect
    raise err(cls.text or description)
aiogram.utils.exceptions.TerminatedByOtherGetUpdates: Terminated by other getupdates request; make sure that only one bot instance is running
2023-06-28:21:15:53,647 ERROR    [dispatcher.py:390] Cause exception while getting updates.
Traceback (most recent call last):
  File "C:\Users\prp48\Desktop\Projects\Telegram\TelegramBotShop\venv\lib\site-packages\aiogram\dispatcher\dispatcher.py", line 381, in start_polling
    updates = await self.bot.get_updates(
  File "C:\Users\prp48\Desktop\Projects\Telegram\TelegramBotShop\venv\lib\site-packages\aiogram\bot\bot.py", line 110, in get_updates
    result = await self.request(api.Methods.GET_UPDATES, payload)
  File "C:\Users\prp48\Desktop\Projects\Telegram\TelegramBotShop\venv\lib\site-packages\aiogram\bot\base.py", line 236, in request
    return await api.make_request(await self.get_session(), self.server, self.__token, method, data, files,
  File "C:\Users\prp48\Desktop\Projects\Telegram\TelegramBotShop\venv\lib\site-packages\aiogram\bot\api.py", line 140, in make_request
    return check_result(method, response.content_type, response.status, await response.text())
  File "C:\Users\prp48\Desktop\Projects\Telegram\TelegramBotShop\venv\lib\site-packages\aiogram\bot\api.py", line 119, in check_result
    exceptions.ConflictError.detect(description)
  File "C:\Users\prp48\Desktop\Projects\Telegram\TelegramBotShop\venv\lib\site-packages\aiogram\utils\exceptions.py", line 140, in detect
    raise err(cls.text or description)
aiogram.utils.exceptions.TerminatedByOtherGetUpdates: Terminated by other getupdates request; make sure that only one bot instance is running
2023-06-28:21:15:59,843 WARNING  [logger.py:40] BOT SHUTDOWN
2023-06-28:21:15:59,843 INFO     [dispatcher.py:433] Stop polling...
2023-06-28:21:15:59,844 WARNING  [executor.py:329] Goodbye!
